[14/Nov/2012 13:32:20] DEBUG [mysite:e:\workspace\xz_server_from_git\xzserver\repo.server\xizhi-server\apps\account\views.py:158] login_count: 39 of profile: 2
[14/Nov/2012 13:32:21] WARNING [django.request:e:\server-env\lib\site-packages\django\core\handlers\base.py:142] Not Found: /media/img/
[14/Nov/2012 13:32:21] WARNING [django.request:e:\server-env\lib\site-packages\django\core\handlers\base.py:142] Not Found: /media/img/
[14/Nov/2012 13:32:21] WARNING [django.request:e:\server-env\lib\site-packages\django\core\handlers\base.py:142] Not Found: /media/img/
[14/Nov/2012 13:32:21] WARNING [django.request:e:\server-env\lib\site-packages\django\core\handlers\base.py:142] Not Found: /media/img/
[14/Nov/2012 13:32:33] WARNING [django.request:e:\server-env\lib\site-packages\django\core\handlers\base.py:142] Not Found: /media/img/
[14/Nov/2012 13:32:33] WARNING [django.request:e:\server-env\lib\site-packages\django\core\handlers\base.py:142] Not Found: /media/img/
[14/Nov/2012 13:32:55] WARNING [django.request:e:\server-env\lib\site-packages\django\core\handlers\base.py:142] Not Found: /media/img/
[14/Nov/2012 13:32:55] WARNING [django.request:e:\server-env\lib\site-packages\django\core\handlers\base.py:142] Not Found: /media/img/
[14/Nov/2012 13:32:55] WARNING [django.request:e:\server-env\lib\site-packages\django\core\handlers\base.py:142] Not Found: /media/img/
[14/Nov/2012 13:32:55] WARNING [django.request:e:\server-env\lib\site-packages\django\core\handlers\base.py:142] Not Found: /media/img/
[14/Nov/2012 13:33:29] DEBUG [mysite:e:\workspace\xz_server_from_git\xzserver\repo.server\xizhi-server\apps\account\views.py:158] login_count: 40 of profile: 2
[14/Nov/2012 13:33:30] WARNING [django.request:e:\server-env\lib\site-packages\django\core\handlers\base.py:142] Not Found: /media/img/
[14/Nov/2012 13:33:30] WARNING [django.request:e:\server-env\lib\site-packages\django\core\handlers\base.py:142] Not Found: /media/img/
[14/Nov/2012 13:33:30] WARNING [django.request:e:\server-env\lib\site-packages\django\core\handlers\base.py:142] Not Found: /media/img/
[14/Nov/2012 13:33:30] WARNING [django.request:e:\server-env\lib\site-packages\django\core\handlers\base.py:142] Not Found: /media/img/
[14/Nov/2012 13:33:37] WARNING [django.request:e:\server-env\lib\site-packages\django\core\handlers\base.py:142] Not Found: /media/img/activity/default_poster_pic
[14/Nov/2012 13:33:37] WARNING [django.request:e:\server-env\lib\site-packages\django\core\handlers\base.py:142] Not Found: /media/img/activity/default_poster_pic
[14/Nov/2012 13:33:37] WARNING [django.request:e:\server-env\lib\site-packages\django\core\handlers\base.py:142] Not Found: /media/img/activity/default_poster_pic
[14/Nov/2012 13:33:37] WARNING [django.request:e:\server-env\lib\site-packages\django\core\handlers\base.py:142] Not Found: /media/img/activity/default_poster_pic
[14/Nov/2012 13:33:49] ERROR [django.request:e:\server-env\lib\site-packages\django\core\handlers\base.py:215] Internal Server Error: /profiles/init_pic/
Traceback (most recent call last):
  File "E:\server-env\lib\site-packages\django\core\handlers\base.py", line 111, in get_response
    response = callback(request, *callback_args, **callback_kwargs)
  File "E:\workspace\xz_server_from_GIT\xzserver\repo.server\xizhi-server\apps\profiles\views.py", line 193, in initPic
    file_utils.remove(profile.big_pic)      #remove the original pic of current profile
TypeError: remove() takes exactly 2 arguments (1 given)
[14/Nov/2012 13:33:49] ERROR [django.request:e:\server-env\lib\site-packages\django\core\handlers\base.py:215] Internal Server Error: /profiles/init_pic/
Traceback (most recent call last):
  File "E:\server-env\lib\site-packages\django\core\handlers\base.py", line 111, in get_response
    response = callback(request, *callback_args, **callback_kwargs)
  File "E:\workspace\xz_server_from_GIT\xzserver\repo.server\xizhi-server\apps\profiles\views.py", line 193, in initPic
    file_utils.remove(profile.big_pic)      #remove the original pic of current profile
TypeError: remove() takes exactly 2 arguments (1 given)
[14/Nov/2012 13:33:57] WARNING [django.request:e:\server-env\lib\site-packages\django\core\handlers\base.py:142] Not Found: /media/img/
[14/Nov/2012 13:33:57] WARNING [django.request:e:\server-env\lib\site-packages\django\core\handlers\base.py:142] Not Found: /media/img/
[14/Nov/2012 13:34:00] WARNING [django.request:e:\server-env\lib\site-packages\django\core\handlers\base.py:142] Not Found: /media/img/
[14/Nov/2012 13:34:00] WARNING [django.request:e:\server-env\lib\site-packages\django\core\handlers\base.py:142] Not Found: /media/img/
[14/Nov/2012 13:34:09] WARNING [django.request:e:\server-env\lib\site-packages\django\core\handlers\base.py:142] Not Found: /media/img/
[14/Nov/2012 13:34:09] WARNING [django.request:e:\server-env\lib\site-packages\django\core\handlers\base.py:142] Not Found: /media/img/
[14/Nov/2012 13:34:09] WARNING [django.request:e:\server-env\lib\site-packages\django\core\handlers\base.py:142] Not Found: /media/img/
[14/Nov/2012 13:34:09] WARNING [django.request:e:\server-env\lib\site-packages\django\core\handlers\base.py:142] Not Found: /media/img/
[14/Nov/2012 13:44:21] WARNING [django.request:e:\server-env\lib\site-packages\django\core\handlers\base.py:142] Not Found: /media/img/
[14/Nov/2012 13:44:21] WARNING [django.request:e:\server-env\lib\site-packages\django\core\handlers\base.py:142] Not Found: /media/img/
[14/Nov/2012 13:44:31] WARNING [django.request:e:\server-env\lib\site-packages\django\core\handlers\base.py:142] Not Found: /media/img/
[14/Nov/2012 13:44:31] WARNING [django.request:e:\server-env\lib\site-packages\django\core\handlers\base.py:142] Not Found: /media/img/
[14/Nov/2012 13:49:16] DEBUG [mysite:e:\workspace\xz_server_from_git\xzserver\repo.server\xizhi-server\apps\profiles\views.py:225] (11, 15, 95, 99)
[14/Nov/2012 13:49:19] WARNING [django.request:e:\server-env\lib\site-packages\django\core\handlers\base.py:142] Not Found: /media/img/
[14/Nov/2012 13:49:19] WARNING [django.request:e:\server-env\lib\site-packages\django\core\handlers\base.py:142] Not Found: /media/img/
[14/Nov/2012 13:49:22] WARNING [django.request:e:\server-env\lib\site-packages\django\core\handlers\base.py:142] Not Found: /media/img/
[14/Nov/2012 13:49:22] WARNING [django.request:e:\server-env\lib\site-packages\django\core\handlers\base.py:142] Not Found: /media/img/
[14/Nov/2012 13:49:24] WARNING [django.request:e:\server-env\lib\site-packages\django\core\handlers\base.py:142] Not Found: /media/img/
[14/Nov/2012 13:49:24] WARNING [django.request:e:\server-env\lib\site-packages\django\core\handlers\base.py:142] Not Found: /media/img/
[14/Nov/2012 13:49:24] WARNING [django.request:e:\server-env\lib\site-packages\django\core\handlers\base.py:142] Not Found: /media/img/
[14/Nov/2012 13:49:24] WARNING [django.request:e:\server-env\lib\site-packages\django\core\handlers\base.py:142] Not Found: /media/img/
[14/Nov/2012 14:21:57] DEBUG [mysite:e:\workspace\xz_server_from_git\xzserver\repo.server\xizhi-server\apps\profiles\views.py:225] (146, 0, 220, 74)
[14/Nov/2012 14:31:47] DEBUG [mysite:e:\workspace\xz_server_from_git\xzserver\repo.server\xizhi-server\apps\account\views.py:158] login_count: 41 of profile: 2
[14/Nov/2012 14:31:48] WARNING [django.request:e:\server-env\lib\site-packages\django\core\handlers\base.py:142] Not Found: /media/img/
[14/Nov/2012 14:31:48] WARNING [django.request:e:\server-env\lib\site-packages\django\core\handlers\base.py:142] Not Found: /media/img/
[14/Nov/2012 14:32:40] DEBUG [mysite:e:\workspace\xz_server_from_git\xzserver\repo.server\xizhi-server\apps\account\threads.py:25] Email sending thread started...
[14/Nov/2012 14:32:41] DEBUG [mysite:e:\workspace\xz_server_from_git\xzserver\repo.server\xizhi-server\apps\account\threads.py:33] Email sending thread end
[14/Nov/2012 14:33:57] DEBUG [mysite:e:\workspace\xz_server_from_git\xzserver\repo.server\xizhi-server\apps\account\views.py:158] login_count: 2 of profile: 7
[14/Nov/2012 14:33:58] WARNING [django.request:e:\server-env\lib\site-packages\django\core\handlers\base.py:142] Not Found: /media/img/
[14/Nov/2012 14:33:58] WARNING [django.request:e:\server-env\lib\site-packages\django\core\handlers\base.py:142] Not Found: /media/img/
[14/Nov/2012 14:34:02] WARNING [django.request:e:\server-env\lib\site-packages\django\core\handlers\base.py:142] Not Found: /media/img/profile/975d8dc0-2e23-11e2-8ecc-00e06650caff_b
[14/Nov/2012 14:34:02] WARNING [django.request:e:\server-env\lib\site-packages\django\core\handlers\base.py:142] Not Found: /media/img/profile/975d8dc0-2e23-11e2-8ecc-00e06650caff_b
[14/Nov/2012 14:34:02] WARNING [django.request:e:\server-env\lib\site-packages\django\core\handlers\base.py:142] Not Found: /media/img/
[14/Nov/2012 14:34:02] WARNING [django.request:e:\server-env\lib\site-packages\django\core\handlers\base.py:142] Not Found: /media/img/
[14/Nov/2012 14:34:12] WARNING [django.request:e:\server-env\lib\site-packages\django\core\handlers\base.py:142] Not Found: /media/img/
[14/Nov/2012 14:34:12] WARNING [django.request:e:\server-env\lib\site-packages\django\core\handlers\base.py:142] Not Found: /media/img/
[14/Nov/2012 14:34:12] WARNING [django.request:e:\server-env\lib\site-packages\django\core\handlers\base.py:142] Not Found: /media/img/
[14/Nov/2012 14:34:12] WARNING [django.request:e:\server-env\lib\site-packages\django\core\handlers\base.py:142] Not Found: /media/img/
[14/Nov/2012 14:34:15] WARNING [django.request:e:\server-env\lib\site-packages\django\core\handlers\base.py:142] Not Found: /media/img/
[14/Nov/2012 14:34:15] WARNING [django.request:e:\server-env\lib\site-packages\django\core\handlers\base.py:142] Not Found: /media/img/
[14/Nov/2012 14:34:19] WARNING [django.request:e:\server-env\lib\site-packages\django\core\handlers\base.py:142] Not Found: /media/img/
[14/Nov/2012 14:34:19] WARNING [django.request:e:\server-env\lib\site-packages\django\core\handlers\base.py:142] Not Found: /media/img/
[14/Nov/2012 14:34:19] WARNING [django.request:e:\server-env\lib\site-packages\django\core\handlers\base.py:142] Not Found: /media/img/profile/975d8dc0-2e23-11e2-8ecc-00e06650caff_b
[14/Nov/2012 14:34:19] WARNING [django.request:e:\server-env\lib\site-packages\django\core\handlers\base.py:142] Not Found: /media/img/profile/975d8dc0-2e23-11e2-8ecc-00e06650caff_b
[14/Nov/2012 14:34:20] WARNING [django.request:e:\server-env\lib\site-packages\django\core\handlers\base.py:142] Not Found: /media/img/
[14/Nov/2012 14:34:20] WARNING [django.request:e:\server-env\lib\site-packages\django\core\handlers\base.py:142] Not Found: /media/img/
[14/Nov/2012 14:34:23] WARNING [django.request:e:\server-env\lib\site-packages\django\core\handlers\base.py:142] Not Found: /media/img/
[14/Nov/2012 14:34:23] WARNING [django.request:e:\server-env\lib\site-packages\django\core\handlers\base.py:142] Not Found: /media/img/
[14/Nov/2012 14:39:41] WARNING [django.request:e:\server-env\lib\site-packages\django\core\handlers\base.py:142] Not Found: /media/img/
[14/Nov/2012 14:39:41] WARNING [django.request:e:\server-env\lib\site-packages\django\core\handlers\base.py:142] Not Found: /media/img/
[14/Nov/2012 14:39:41] WARNING [django.request:e:\server-env\lib\site-packages\django\core\handlers\base.py:142] Not Found: /media/img/
[14/Nov/2012 14:39:41] WARNING [django.request:e:\server-env\lib\site-packages\django\core\handlers\base.py:142] Not Found: /media/img/
[14/Nov/2012 14:40:07] DEBUG [mysite:e:\workspace\xz_server_from_git\xzserver\repo.server\xizhi-server\apps\account\views.py:158] login_count: 3 of profile: 7
[14/Nov/2012 14:40:08] WARNING [django.request:e:\server-env\lib\site-packages\django\core\handlers\base.py:142] Not Found: /media/img/
[14/Nov/2012 14:40:08] WARNING [django.request:e:\server-env\lib\site-packages\django\core\handlers\base.py:142] Not Found: /media/img/
[14/Nov/2012 14:40:08] WARNING [django.request:e:\server-env\lib\site-packages\django\core\handlers\base.py:142] Not Found: /media/img/
[14/Nov/2012 14:40:08] WARNING [django.request:e:\server-env\lib\site-packages\django\core\handlers\base.py:142] Not Found: /media/img/
[14/Nov/2012 14:40:54] WARNING [django.request:e:\server-env\lib\site-packages\django\core\handlers\base.py:142] Not Found: /media/img/
[14/Nov/2012 14:40:54] WARNING [django.request:e:\server-env\lib\site-packages\django\core\handlers\base.py:142] Not Found: /media/img/
[14/Nov/2012 14:43:47] DEBUG [mysite:e:\workspace\xz_server_from_git\xzserver\repo.server\xizhi-server\apps\account\views.py:158] login_count: 4 of profile: 7
[14/Nov/2012 14:43:48] WARNING [django.request:e:\server-env\lib\site-packages\django\core\handlers\base.py:142] Not Found: /media/img/
[14/Nov/2012 14:43:48] WARNING [django.request:e:\server-env\lib\site-packages\django\core\handlers\base.py:142] Not Found: /media/img/
[14/Nov/2012 14:43:48] WARNING [django.request:e:\server-env\lib\site-packages\django\core\handlers\base.py:142] Not Found: /media/img/
[14/Nov/2012 14:43:48] WARNING [django.request:e:\server-env\lib\site-packages\django\core\handlers\base.py:142] Not Found: /media/img/
[14/Nov/2012 14:50:08] DEBUG [mysite:e:\workspace\xz_server_from_git\xzserver\repo.server\xizhi-server\apps\account\views.py:161] login_count: 5 of profile: 7
[14/Nov/2012 14:50:09] WARNING [django.request:e:\server-env\lib\site-packages\django\core\handlers\base.py:142] Not Found: /media/img/
[14/Nov/2012 14:50:09] WARNING [django.request:e:\server-env\lib\site-packages\django\core\handlers\base.py:142] Not Found: /media/img/
[14/Nov/2012 14:50:21] WARNING [django.request:e:\server-env\lib\site-packages\django\core\handlers\base.py:142] Not Found: /media/img/
[14/Nov/2012 14:50:21] WARNING [django.request:e:\server-env\lib\site-packages\django\core\handlers\base.py:142] Not Found: /media/img/
[14/Nov/2012 14:50:21] WARNING [django.request:e:\server-env\lib\site-packages\django\core\handlers\base.py:142] Not Found: /media/img/
[14/Nov/2012 14:50:21] WARNING [django.request:e:\server-env\lib\site-packages\django\core\handlers\base.py:142] Not Found: /media/img/
[14/Nov/2012 14:50:41] WARNING [django.request:e:\server-env\lib\site-packages\django\core\handlers\base.py:142] Not Found: /media/img/
[14/Nov/2012 14:50:41] WARNING [django.request:e:\server-env\lib\site-packages\django\core\handlers\base.py:142] Not Found: /media/img/
[14/Nov/2012 14:50:41] WARNING [django.request:e:\server-env\lib\site-packages\django\core\handlers\base.py:142] Not Found: /media/img/
[14/Nov/2012 14:50:41] WARNING [django.request:e:\server-env\lib\site-packages\django\core\handlers\base.py:142] Not Found: /media/img/
[14/Nov/2012 14:50:46] WARNING [django.request:e:\server-env\lib\site-packages\django\core\handlers\base.py:142] Not Found: /media/img/
[14/Nov/2012 14:50:46] WARNING [django.request:e:\server-env\lib\site-packages\django\core\handlers\base.py:142] Not Found: /media/img/
[14/Nov/2012 14:50:46] WARNING [django.request:e:\server-env\lib\site-packages\django\core\handlers\base.py:142] Not Found: /media/img/
[14/Nov/2012 14:50:46] WARNING [django.request:e:\server-env\lib\site-packages\django\core\handlers\base.py:142] Not Found: /media/img/
[14/Nov/2012 14:51:21] DEBUG [mysite:e:\workspace\xz_server_from_git\xzserver\repo.server\xizhi-server\apps\account\views.py:161] login_count: 6 of profile: 7
[14/Nov/2012 14:51:22] WARNING [django.request:e:\server-env\lib\site-packages\django\core\handlers\base.py:142] Not Found: /media/img/
[14/Nov/2012 14:51:22] WARNING [django.request:e:\server-env\lib\site-packages\django\core\handlers\base.py:142] Not Found: /media/img/
[14/Nov/2012 14:51:22] WARNING [django.request:e:\server-env\lib\site-packages\django\core\handlers\base.py:142] Not Found: /media/img/
[14/Nov/2012 14:51:22] WARNING [django.request:e:\server-env\lib\site-packages\django\core\handlers\base.py:142] Not Found: /media/img/
[14/Nov/2012 14:51:30] WARNING [django.request:e:\server-env\lib\site-packages\django\core\handlers\base.py:142] Not Found: /media/img/
[14/Nov/2012 14:51:30] WARNING [django.request:e:\server-env\lib\site-packages\django\core\handlers\base.py:142] Not Found: /media/img/
[14/Nov/2012 14:51:38] WARNING [django.request:e:\server-env\lib\site-packages\django\core\handlers\base.py:142] Not Found: /media/img/
[14/Nov/2012 14:51:38] WARNING [django.request:e:\server-env\lib\site-packages\django\core\handlers\base.py:142] Not Found: /media/img/
[14/Nov/2012 14:51:39] WARNING [django.request:e:\server-env\lib\site-packages\django\core\handlers\base.py:142] Not Found: /media/img/
[14/Nov/2012 14:51:39] WARNING [django.request:e:\server-env\lib\site-packages\django\core\handlers\base.py:142] Not Found: /media/img/
[14/Nov/2012 14:51:50] WARNING [django.request:e:\server-env\lib\site-packages\django\core\handlers\base.py:142] Not Found: /media/img/
[14/Nov/2012 14:51:50] WARNING [django.request:e:\server-env\lib\site-packages\django\core\handlers\base.py:142] Not Found: /media/img/
[14/Nov/2012 14:51:51] WARNING [django.request:e:\server-env\lib\site-packages\django\core\handlers\base.py:142] Not Found: /media/img/
[14/Nov/2012 14:51:51] WARNING [django.request:e:\server-env\lib\site-packages\django\core\handlers\base.py:142] Not Found: /media/img/
[14/Nov/2012 14:52:40] WARNING [django.request:e:\server-env\lib\site-packages\django\core\handlers\base.py:142] Not Found: /media/img/
[14/Nov/2012 14:52:40] WARNING [django.request:e:\server-env\lib\site-packages\django\core\handlers\base.py:142] Not Found: /media/img/
[14/Nov/2012 14:52:40] WARNING [django.request:e:\server-env\lib\site-packages\django\core\handlers\base.py:142] Not Found: /media/img/
[14/Nov/2012 14:52:40] WARNING [django.request:e:\server-env\lib\site-packages\django\core\handlers\base.py:142] Not Found: /media/img/
[14/Nov/2012 14:53:51] DEBUG [mysite:e:\workspace\xz_server_from_git\xzserver\repo.server\xizhi-server\apps\account\views.py:161] login_count: 7 of profile: 7
[14/Nov/2012 14:53:52] WARNING [django.request:e:\server-env\lib\site-packages\django\core\handlers\base.py:142] Not Found: /media/img/
[14/Nov/2012 14:53:52] WARNING [django.request:e:\server-env\lib\site-packages\django\core\handlers\base.py:142] Not Found: /media/img/
[14/Nov/2012 14:53:52] WARNING [django.request:e:\server-env\lib\site-packages\django\core\handlers\base.py:142] Not Found: /media/img/
[14/Nov/2012 14:53:52] WARNING [django.request:e:\server-env\lib\site-packages\django\core\handlers\base.py:142] Not Found: /media/img/
[14/Nov/2012 15:18:15] WARNING [django.request:e:\server-env\lib\site-packages\django\core\handlers\base.py:142] Not Found: /media/img/
[14/Nov/2012 15:18:15] WARNING [django.request:e:\server-env\lib\site-packages\django\core\handlers\base.py:142] Not Found: /media/img/
[14/Nov/2012 15:18:15] WARNING [django.request:e:\server-env\lib\site-packages\django\core\handlers\base.py:142] Not Found: /media/img/
[14/Nov/2012 15:18:15] WARNING [django.request:e:\server-env\lib\site-packages\django\core\handlers\base.py:142] Not Found: /media/img/
[14/Nov/2012 15:18:23] WARNING [django.request:e:\server-env\lib\site-packages\django\core\handlers\base.py:142] Not Found: /account/login/
[14/Nov/2012 15:18:23] WARNING [django.request:e:\server-env\lib\site-packages\django\core\handlers\base.py:142] Not Found: /account/login/
[14/Nov/2012 15:18:32] WARNING [django.request:e:\server-env\lib\site-packages\django\core\handlers\base.py:142] Not Found: /media/img/
[14/Nov/2012 15:18:32] WARNING [django.request:e:\server-env\lib\site-packages\django\core\handlers\base.py:142] Not Found: /media/img/
[14/Nov/2012 15:18:33] WARNING [django.request:e:\server-env\lib\site-packages\django\core\handlers\base.py:142] Not Found: /media/img/
[14/Nov/2012 15:18:33] WARNING [django.request:e:\server-env\lib\site-packages\django\core\handlers\base.py:142] Not Found: /media/img/
[14/Nov/2012 15:18:55] WARNING [django.request:e:\server-env\lib\site-packages\django\core\handlers\base.py:142] Not Found: /media/img/
[14/Nov/2012 15:18:55] WARNING [django.request:e:\server-env\lib\site-packages\django\core\handlers\base.py:142] Not Found: /media/img/
[14/Nov/2012 15:18:55] WARNING [django.request:e:\server-env\lib\site-packages\django\core\handlers\base.py:142] Not Found: /media/img/
[14/Nov/2012 15:18:55] WARNING [django.request:e:\server-env\lib\site-packages\django\core\handlers\base.py:142] Not Found: /media/img/
[14/Nov/2012 15:19:00] ERROR [django.request:e:\server-env\lib\site-packages\django\core\handlers\base.py:215] Internal Server Error: /account/login/
Traceback (most recent call last):
  File "E:\server-env\lib\site-packages\django\core\handlers\base.py", line 129, in get_response
    raise ValueError("The view %s.%s didn't return an HttpResponse object." % (callback.__module__, view_name))
ValueError: The view protocol.decorators.getIsForbidden didn't return an HttpResponse object.
[14/Nov/2012 15:19:00] ERROR [django.request:e:\server-env\lib\site-packages\django\core\handlers\base.py:215] Internal Server Error: /account/login/
Traceback (most recent call last):
  File "E:\server-env\lib\site-packages\django\core\handlers\base.py", line 129, in get_response
    raise ValueError("The view %s.%s didn't return an HttpResponse object." % (callback.__module__, view_name))
ValueError: The view protocol.decorators.getIsForbidden didn't return an HttpResponse object.
[14/Nov/2012 15:20:42] DEBUG [mysite:e:\workspace\xz_server_from_git\xzserver\repo.server\xizhi-server\apps\account\views.py:160] login_count: 8 of profile: 7
[14/Nov/2012 15:20:43] WARNING [django.request:e:\server-env\lib\site-packages\django\core\handlers\base.py:142] Not Found: /media/img/
[14/Nov/2012 15:20:43] WARNING [django.request:e:\server-env\lib\site-packages\django\core\handlers\base.py:142] Not Found: /media/img/
[14/Nov/2012 15:20:43] WARNING [django.request:e:\server-env\lib\site-packages\django\core\handlers\base.py:142] Not Found: /media/img/
[14/Nov/2012 15:20:43] WARNING [django.request:e:\server-env\lib\site-packages\django\core\handlers\base.py:142] Not Found: /media/img/
[14/Nov/2012 15:20:50] WARNING [django.request:e:\server-env\lib\site-packages\django\core\handlers\base.py:142] Not Found: /account/login/
[14/Nov/2012 15:20:50] WARNING [django.request:e:\server-env\lib\site-packages\django\core\handlers\base.py:142] Not Found: /account/login/
[14/Nov/2012 15:20:51] WARNING [django.request:e:\server-env\lib\site-packages\django\core\handlers\base.py:142] Not Found: /media/img/
[14/Nov/2012 15:20:51] WARNING [django.request:e:\server-env\lib\site-packages\django\core\handlers\base.py:142] Not Found: /media/img/
[14/Nov/2012 15:20:52] WARNING [django.request:e:\server-env\lib\site-packages\django\core\handlers\base.py:142] Not Found: /media/img/
[14/Nov/2012 15:20:52] WARNING [django.request:e:\server-env\lib\site-packages\django\core\handlers\base.py:142] Not Found: /media/img/
[14/Nov/2012 15:24:31] WARNING [django.request:e:\server-env\lib\site-packages\django\core\handlers\base.py:142] Not Found: /account/login/
[14/Nov/2012 15:24:31] WARNING [django.request:e:\server-env\lib\site-packages\django\core\handlers\base.py:142] Not Found: /account/login/
[14/Nov/2012 15:39:39] DEBUG [mysite:e:\workspace\xz_server_from_git\xzserver\repo.server\xizhi-server\apps\account\views.py:160] login_count: 9 of profile: 7
[14/Nov/2012 15:39:40] WARNING [django.request:e:\server-env\lib\site-packages\django\core\handlers\base.py:142] Not Found: /media/img/
[14/Nov/2012 15:39:40] WARNING [django.request:e:\server-env\lib\site-packages\django\core\handlers\base.py:142] Not Found: /media/img/
[14/Nov/2012 15:41:10] WARNING [django.request:e:\server-env\lib\site-packages\django\core\handlers\base.py:142] Not Found: /account/login/
[14/Nov/2012 15:41:10] WARNING [django.request:e:\server-env\lib\site-packages\django\core\handlers\base.py:142] Not Found: /account/login/
[14/Nov/2012 15:41:15] WARNING [django.request:e:\server-env\lib\site-packages\django\core\handlers\base.py:142] Not Found: /account/reset_passwd/
[14/Nov/2012 15:41:15] WARNING [django.request:e:\server-env\lib\site-packages\django\core\handlers\base.py:142] Not Found: /account/reset_passwd/
[14/Nov/2012 15:43:21] DEBUG [mysite:e:\workspace\xz_server_from_git\xzserver\repo.server\xizhi-server\apps\account\threads.py:25] Email sending thread started...
[14/Nov/2012 15:43:24] DEBUG [mysite:e:\workspace\xz_server_from_git\xzserver\repo.server\xizhi-server\apps\account\threads.py:33] Email sending thread end
[14/Nov/2012 15:48:19] DEBUG [mysite:e:\workspace\xz_server_from_git\xzserver\repo.server\xizhi-server\apps\account\views.py:160] login_count: 1 of profile: 10
[14/Nov/2012 15:51:04] WARNING [django.request:e:\server-env\lib\site-packages\django\core\handlers\base.py:142] Not Found: /account/login/
[14/Nov/2012 15:51:04] WARNING [django.request:e:\server-env\lib\site-packages\django\core\handlers\base.py:142] Not Found: /account/login/
[14/Nov/2012 15:52:52] WARNING [django.request:e:\server-env\lib\site-packages\django\core\handlers\base.py:142] Not Found: /media/img/
[14/Nov/2012 15:52:52] WARNING [django.request:e:\server-env\lib\site-packages\django\core\handlers\base.py:142] Not Found: /media/img/
[14/Nov/2012 15:52:52] WARNING [django.request:e:\server-env\lib\site-packages\django\core\handlers\base.py:142] Not Found: /media/img/
[14/Nov/2012 15:52:52] WARNING [django.request:e:\server-env\lib\site-packages\django\core\handlers\base.py:142] Not Found: /media/img/
[14/Nov/2012 15:53:03] WARNING [django.request:e:\server-env\lib\site-packages\django\core\handlers\base.py:142] Not Found: /media/img/
[14/Nov/2012 15:53:03] WARNING [django.request:e:\server-env\lib\site-packages\django\core\handlers\base.py:142] Not Found: /media/img/
[14/Nov/2012 15:54:58] WARNING [django.request:e:\server-env\lib\site-packages\django\core\handlers\base.py:142] Not Found: /media/img/
[14/Nov/2012 15:54:58] WARNING [django.request:e:\server-env\lib\site-packages\django\core\handlers\base.py:142] Not Found: /media/img/
[14/Nov/2012 15:56:24] DEBUG [mysite:e:\workspace\xz_server_from_git\xzserver\repo.server\xizhi-server\apps\profiles\views.py:225] (10, 13, 110, 113)
[14/Nov/2012 16:27:14] WARNING [django.request:e:\server-env\lib\site-packages\django\core\handlers\base.py:142] Not Found: /media/img/
[14/Nov/2012 16:27:14] WARNING [django.request:e:\server-env\lib\site-packages\django\core\handlers\base.py:142] Not Found: /media/img/
[14/Nov/2012 16:27:14] WARNING [django.request:e:\server-env\lib\site-packages\django\core\handlers\base.py:142] Not Found: /media/img/
[14/Nov/2012 16:27:14] WARNING [django.request:e:\server-env\lib\site-packages\django\core\handlers\base.py:142] Not Found: /media/img/
[14/Nov/2012 16:27:18] WARNING [django.request:e:\server-env\lib\site-packages\django\core\handlers\base.py:142] Not Found: /media/img/
[14/Nov/2012 16:27:18] WARNING [django.request:e:\server-env\lib\site-packages\django\core\handlers\base.py:142] Not Found: /media/img/
[14/Nov/2012 16:27:18] WARNING [django.request:e:\server-env\lib\site-packages\django\core\handlers\base.py:142] Not Found: /media/img/profile/975d8dc0-2e23-11e2-8ecc-00e06650caff_b
[14/Nov/2012 16:27:18] WARNING [django.request:e:\server-env\lib\site-packages\django\core\handlers\base.py:142] Not Found: /media/img/profile/975d8dc0-2e23-11e2-8ecc-00e06650caff_b
[14/Nov/2012 16:31:19] WARNING [django.request:e:\server-env\lib\site-packages\django\core\handlers\base.py:142] Not Found: /media/img/profile/975d8dc0-2e23-11e2-8ecc-00e06650caff_b
[14/Nov/2012 16:31:19] WARNING [django.request:e:\server-env\lib\site-packages\django\core\handlers\base.py:142] Not Found: /media/img/profile/975d8dc0-2e23-11e2-8ecc-00e06650caff_b
[14/Nov/2012 16:31:19] WARNING [django.request:e:\server-env\lib\site-packages\django\core\handlers\base.py:142] Not Found: /media/img/
[14/Nov/2012 16:31:19] WARNING [django.request:e:\server-env\lib\site-packages\django\core\handlers\base.py:142] Not Found: /media/img/
[14/Nov/2012 16:31:39] WARNING [django.request:e:\server-env\lib\site-packages\django\core\handlers\base.py:142] Not Found: /media/img/profile/975d8dc0-2e23-11e2-8ecc-00e06650caff_b
[14/Nov/2012 16:31:39] WARNING [django.request:e:\server-env\lib\site-packages\django\core\handlers\base.py:142] Not Found: /media/img/profile/975d8dc0-2e23-11e2-8ecc-00e06650caff_b
[14/Nov/2012 16:35:53] WARNING [django.request:e:\server-env\lib\site-packages\django\core\handlers\base.py:142] Not Found: /media/img/profile/975d8dc0-2e23-11e2-8ecc-00e06650caff_b
[14/Nov/2012 16:35:53] WARNING [django.request:e:\server-env\lib\site-packages\django\core\handlers\base.py:142] Not Found: /media/img/profile/975d8dc0-2e23-11e2-8ecc-00e06650caff_b
[14/Nov/2012 16:36:37] WARNING [django.request:e:\server-env\lib\site-packages\django\core\handlers\base.py:142] Not Found: /media/img/
[14/Nov/2012 16:36:37] WARNING [django.request:e:\server-env\lib\site-packages\django\core\handlers\base.py:142] Not Found: /media/img/
[14/Nov/2012 16:36:37] WARNING [django.request:e:\server-env\lib\site-packages\django\core\handlers\base.py:142] Not Found: /media/img/
[14/Nov/2012 16:36:37] WARNING [django.request:e:\server-env\lib\site-packages\django\core\handlers\base.py:142] Not Found: /media/img/
[14/Nov/2012 16:36:48] DEBUG [mysite:e:\workspace\xz_server_from_git\xzserver\repo.server\xizhi-server\apps\account\views.py:160] login_count: 42 of profile: 2
[14/Nov/2012 16:36:49] WARNING [django.request:e:\server-env\lib\site-packages\django\core\handlers\base.py:142] Not Found: /media/img/
[14/Nov/2012 16:36:49] WARNING [django.request:e:\server-env\lib\site-packages\django\core\handlers\base.py:142] Not Found: /media/img/
[14/Nov/2012 16:36:50] WARNING [django.request:e:\server-env\lib\site-packages\django\core\handlers\base.py:142] Not Found: /media/img/
[14/Nov/2012 16:36:50] WARNING [django.request:e:\server-env\lib\site-packages\django\core\handlers\base.py:142] Not Found: /media/img/
[14/Nov/2012 16:36:52] WARNING [django.request:e:\server-env\lib\site-packages\django\core\handlers\base.py:142] Not Found: /media/img/profile/975d8dc0-2e23-11e2-8ecc-00e06650caff_b
[14/Nov/2012 16:36:52] WARNING [django.request:e:\server-env\lib\site-packages\django\core\handlers\base.py:142] Not Found: /media/img/profile/975d8dc0-2e23-11e2-8ecc-00e06650caff_b
[14/Nov/2012 16:37:23] WARNING [django.request:e:\server-env\lib\site-packages\django\core\handlers\base.py:142] Not Found: /media/img/
[14/Nov/2012 16:37:23] WARNING [django.request:e:\server-env\lib\site-packages\django\core\handlers\base.py:142] Not Found: /media/img/
[14/Nov/2012 16:37:23] WARNING [django.request:e:\server-env\lib\site-packages\django\core\handlers\base.py:142] Not Found: /media/img/
[14/Nov/2012 16:37:23] WARNING [django.request:e:\server-env\lib\site-packages\django\core\handlers\base.py:142] Not Found: /media/img/
[14/Nov/2012 16:37:25] WARNING [django.request:e:\server-env\lib\site-packages\django\core\handlers\base.py:142] Not Found: /media/img/profile/975d8dc0-2e23-11e2-8ecc-00e06650caff_b
[14/Nov/2012 16:37:25] WARNING [django.request:e:\server-env\lib\site-packages\django\core\handlers\base.py:142] Not Found: /media/img/profile/975d8dc0-2e23-11e2-8ecc-00e06650caff_b
[14/Nov/2012 16:38:09] DEBUG [mysite:e:\workspace\xz_server_from_git\xzserver\repo.server\xizhi-server\apps\profiles\views.py:225] (16, 20, 116, 120)
[14/Nov/2012 16:38:16] WARNING [django.request:e:\server-env\lib\site-packages\django\core\handlers\base.py:142] Not Found: /media/img/
[14/Nov/2012 16:38:16] WARNING [django.request:e:\server-env\lib\site-packages\django\core\handlers\base.py:142] Not Found: /media/img/
[14/Nov/2012 16:38:16] WARNING [django.request:e:\server-env\lib\site-packages\django\core\handlers\base.py:142] Not Found: /media/img/
[14/Nov/2012 16:38:16] WARNING [django.request:e:\server-env\lib\site-packages\django\core\handlers\base.py:142] Not Found: /media/img/
[14/Nov/2012 16:38:23] WARNING [django.request:e:\server-env\lib\site-packages\django\core\handlers\base.py:142] Not Found: /media/img/
[14/Nov/2012 16:38:23] WARNING [django.request:e:\server-env\lib\site-packages\django\core\handlers\base.py:142] Not Found: /media/img/
[14/Nov/2012 16:38:23] WARNING [django.request:e:\server-env\lib\site-packages\django\core\handlers\base.py:142] Not Found: /media/img/
[14/Nov/2012 16:38:23] WARNING [django.request:e:\server-env\lib\site-packages\django\core\handlers\base.py:142] Not Found: /media/img/
[14/Nov/2012 16:38:34] WARNING [django.request:e:\server-env\lib\site-packages\django\core\handlers\base.py:142] Not Found: /media/img/
[14/Nov/2012 16:38:34] WARNING [django.request:e:\server-env\lib\site-packages\django\core\handlers\base.py:142] Not Found: /media/img/
[14/Nov/2012 16:38:54] WARNING [django.request:e:\server-env\lib\site-packages\django\core\handlers\base.py:142] Not Found: /media/img/
[14/Nov/2012 16:38:54] WARNING [django.request:e:\server-env\lib\site-packages\django\core\handlers\base.py:142] Not Found: /media/img/
[14/Nov/2012 16:38:56] WARNING [django.request:e:\server-env\lib\site-packages\django\core\handlers\base.py:142] Not Found: /media/img/profile/9e78450f-2e36-11e2-9847-00e06650caff_b
[14/Nov/2012 16:38:56] WARNING [django.request:e:\server-env\lib\site-packages\django\core\handlers\base.py:142] Not Found: /media/img/profile/9e78450f-2e36-11e2-9847-00e06650caff_b
[14/Nov/2012 16:39:57] WARNING [django.request:e:\server-env\lib\site-packages\django\core\handlers\base.py:142] Not Found: /media/img/
[14/Nov/2012 16:39:57] WARNING [django.request:e:\server-env\lib\site-packages\django\core\handlers\base.py:142] Not Found: /media/img/
[14/Nov/2012 16:39:57] WARNING [django.request:e:\server-env\lib\site-packages\django\core\handlers\base.py:142] Not Found: /media/img/
[14/Nov/2012 16:39:57] WARNING [django.request:e:\server-env\lib\site-packages\django\core\handlers\base.py:142] Not Found: /media/img/
[14/Nov/2012 16:40:12] WARNING [django.request:e:\server-env\lib\site-packages\django\core\handlers\base.py:142] Not Found: /media/img/
[14/Nov/2012 16:40:12] WARNING [django.request:e:\server-env\lib\site-packages\django\core\handlers\base.py:142] Not Found: /media/img/
[14/Nov/2012 16:40:12] WARNING [django.request:e:\server-env\lib\site-packages\django\core\handlers\base.py:142] Not Found: /media/img/
[14/Nov/2012 16:40:12] WARNING [django.request:e:\server-env\lib\site-packages\django\core\handlers\base.py:142] Not Found: /media/img/
[14/Nov/2012 16:40:26] DEBUG [mysite:e:\workspace\xz_server_from_git\xzserver\repo.server\xizhi-server\apps\profiles\views.py:225] (11, 16, 90, 95)
[14/Nov/2012 16:40:29] WARNING [django.request:e:\server-env\lib\site-packages\django\core\handlers\base.py:142] Not Found: /media/img/
[14/Nov/2012 16:40:29] WARNING [django.request:e:\server-env\lib\site-packages\django\core\handlers\base.py:142] Not Found: /media/img/
[14/Nov/2012 16:41:34] WARNING [django.request:e:\server-env\lib\site-packages\django\core\handlers\base.py:142] Not Found: /media/img/
[14/Nov/2012 16:41:34] WARNING [django.request:e:\server-env\lib\site-packages\django\core\handlers\base.py:142] Not Found: /media/img/
[14/Nov/2012 16:41:34] WARNING [django.request:e:\server-env\lib\site-packages\django\core\handlers\base.py:142] Not Found: /media/img/
[14/Nov/2012 16:41:34] WARNING [django.request:e:\server-env\lib\site-packages\django\core\handlers\base.py:142] Not Found: /media/img/
[14/Nov/2012 17:23:54] DEBUG [mysite:e:\workspace\xz_server_from_git\xzserver\repo.server\xizhi-server\apps\account\views.py:160] login_count: 43 of profile: 2
[14/Nov/2012 17:24:07] DEBUG [mysite:e:\workspace\xz_server_from_git\xzserver\repo.server\xizhi-server\apps\profiles\views.py:225] (0, 0, 100, 100)
[14/Nov/2012 17:39:04] DEBUG [mysite:e:\workspace\xz_server_from_git\xzserver\repo.server\xizhi-server\apps\profiles\views.py:225] (41, 74, 101, 134)
[15/Nov/2012 09:17:36] WARNING [django.request:e:\server-env\lib\site-packages\django\core\handlers\base.py:142] Not Found: /favicon.ico
[15/Nov/2012 09:17:36] WARNING [django.request:e:\server-env\lib\site-packages\django\core\handlers\base.py:142] Not Found: /favicon.ico
[15/Nov/2012 09:17:36] WARNING [django.request:e:\server-env\lib\site-packages\django\core\handlers\base.py:142] Not Found: /favicon.ico
[15/Nov/2012 09:17:36] WARNING [django.request:e:\server-env\lib\site-packages\django\core\handlers\base.py:142] Not Found: /favicon.ico
[15/Nov/2012 09:17:36] WARNING [django.request:e:\server-env\lib\site-packages\django\core\handlers\base.py:142] Not Found: /favicon.ico
[15/Nov/2012 09:17:36] WARNING [django.request:e:\server-env\lib\site-packages\django\core\handlers\base.py:142] Not Found: /favicon.ico
[15/Nov/2012 09:17:50] DEBUG [mysite:e:\workspace\xz_server_from_git\xzserver\repo.server\xizhi-server\apps\account\views.py:160] login_count: 10 of profile: 7
[15/Nov/2012 09:18:03] DEBUG [mysite:e:\workspace\xz_server_from_git\xzserver\repo.server\xizhi-server\apps\common\img_utils.py:54] File with name 4d75e000-2ec2-11e2-a14d-00e06650caff saved
[15/Nov/2012 09:18:09] DEBUG [mysite:e:\workspace\xz_server_from_git\xzserver\repo.server\xizhi-server\apps\profiles\views.py:239] (56, 9, 116, 69)
[15/Nov/2012 09:18:09] DEBUG [mysite:e:\workspace\xz_server_from_git\xzserver\repo.server\xizhi-server\apps\common\img_utils.py:54] File with name 510f0c51-2ec2-11e2-8fe4-00e06650caff_b saved
[15/Nov/2012 09:18:09] DEBUG [mysite:e:\workspace\xz_server_from_git\xzserver\repo.server\xizhi-server\apps\common\img_utils.py:54] File with name 51117d4f-2ec2-11e2-a8c0-00e06650caff_n saved
[15/Nov/2012 09:18:09] DEBUG [mysite:e:\workspace\xz_server_from_git\xzserver\repo.server\xizhi-server\apps\common\img_utils.py:54] File with name 51117d50-2ec2-11e2-8321-00e06650caff_s saved
[15/Nov/2012 09:18:09] INFO [mysite:e:\workspace\xz_server_from_git\xzserver\repo.server\xizhi-server\apps\common\file_utils.py:27] delete file E:/media/img\default_pic error
[15/Nov/2012 09:18:16] DEBUG [mysite:e:\workspace\xz_server_from_git\xzserver\repo.server\xizhi-server\apps\common\img_utils.py:54] File with name 5574fe80-2ec2-11e2-b002-00e06650caff saved
[15/Nov/2012 09:18:18] DEBUG [mysite:e:\workspace\xz_server_from_git\xzserver\repo.server\xizhi-server\apps\profiles\views.py:162] Deleted picture profile/5574fe80-2ec2-11e2-b002-00e06650caff successfully
[15/Nov/2012 09:18:18] ERROR [django.request:e:\server-env\lib\site-packages\django\core\handlers\base.py:215] Internal Server Error: /profiles/cancel_pic_setup/
Traceback (most recent call last):
  File "E:\server-env\lib\site-packages\django\core\handlers\base.py", line 111, in get_response
    response = callback(request, *callback_args, **callback_kwargs)
  File "E:\workspace\xz_server_from_GIT\xzserver\repo.server\xizhi-server\apps\profiles\views.py", line 167, in cancelPicSetup
    profile.save()
  File "E:\server-env\lib\site-packages\django\db\models\base.py", line 463, in save
    self.save_base(using=using, force_insert=force_insert, force_update=force_update)
  File "E:\server-env\lib\site-packages\django\db\models\base.py", line 529, in save_base
    rows = manager.using(using).filter(pk=pk_val)._update(values)
  File "E:\server-env\lib\site-packages\django\db\models\query.py", line 560, in _update
    return query.get_compiler(self.db).execute_sql(None)
  File "E:\server-env\lib\site-packages\django\db\models\sql\compiler.py", line 986, in execute_sql
    cursor = super(SQLUpdateCompiler, self).execute_sql(result_type)
  File "E:\server-env\lib\site-packages\django\db\models\sql\compiler.py", line 818, in execute_sql
    cursor.execute(sql, params)
  File "E:\server-env\lib\site-packages\debug_toolbar\panels\sql.py", line 117, in execute
    return self.cursor.execute(sql, params)
  File "E:\server-env\lib\site-packages\django\db\backends\mysql\base.py", line 114, in execute
    return self.cursor.execute(query, args)
  File "E:\server-env\lib\site-packages\MySQLdb\cursors.py", line 173, in execute
    self.errorhandler(self, exc, value)
  File "E:\server-env\lib\site-packages\MySQLdb\connections.py", line 36, in defaulterrorhandler
    raise errorclass, errorvalue
IntegrityError: (1048, "Column 'tmp_pic' cannot be null")
[15/Nov/2012 09:18:18] ERROR [django.request:e:\server-env\lib\site-packages\django\core\handlers\base.py:215] Internal Server Error: /profiles/cancel_pic_setup/
Traceback (most recent call last):
  File "E:\server-env\lib\site-packages\django\core\handlers\base.py", line 111, in get_response
    response = callback(request, *callback_args, **callback_kwargs)
  File "E:\workspace\xz_server_from_GIT\xzserver\repo.server\xizhi-server\apps\profiles\views.py", line 167, in cancelPicSetup
    profile.save()
  File "E:\server-env\lib\site-packages\django\db\models\base.py", line 463, in save
    self.save_base(using=using, force_insert=force_insert, force_update=force_update)
  File "E:\server-env\lib\site-packages\django\db\models\base.py", line 529, in save_base
    rows = manager.using(using).filter(pk=pk_val)._update(values)
  File "E:\server-env\lib\site-packages\django\db\models\query.py", line 560, in _update
    return query.get_compiler(self.db).execute_sql(None)
  File "E:\server-env\lib\site-packages\django\db\models\sql\compiler.py", line 986, in execute_sql
    cursor = super(SQLUpdateCompiler, self).execute_sql(result_type)
  File "E:\server-env\lib\site-packages\django\db\models\sql\compiler.py", line 818, in execute_sql
    cursor.execute(sql, params)
  File "E:\server-env\lib\site-packages\debug_toolbar\panels\sql.py", line 117, in execute
    return self.cursor.execute(sql, params)
  File "E:\server-env\lib\site-packages\django\db\backends\mysql\base.py", line 114, in execute
    return self.cursor.execute(query, args)
  File "E:\server-env\lib\site-packages\MySQLdb\cursors.py", line 173, in execute
    self.errorhandler(self, exc, value)
  File "E:\server-env\lib\site-packages\MySQLdb\connections.py", line 36, in defaulterrorhandler
    raise errorclass, errorvalue
IntegrityError: (1048, "Column 'tmp_pic' cannot be null")
[15/Nov/2012 09:35:56] DEBUG [mysite:e:\workspace\xz_server_from_git\xzserver\repo.server\xizhi-server\apps\profiles\views.py:164] Picture profile/5574fe80-2ec2-11e2-b002-00e06650caff not found when deleted
[15/Nov/2012 09:36:02] DEBUG [mysite:e:\workspace\xz_server_from_git\xzserver\repo.server\xizhi-server\apps\common\img_utils.py:54] File with name d0d53e80-2ec4-11e2-907c-00e06650caff saved
[15/Nov/2012 09:36:04] DEBUG [mysite:e:\workspace\xz_server_from_git\xzserver\repo.server\xizhi-server\apps\profiles\views.py:162] Deleted picture profile/d0d53e80-2ec4-11e2-907c-00e06650caff successfully
[15/Nov/2012 09:45:53] WARNING [django.request:e:\server-env\lib\site-packages\django\core\handlers\base.py:142] Not Found: /media/img/activity/default_poster_pic
[15/Nov/2012 09:45:53] WARNING [django.request:e:\server-env\lib\site-packages\django\core\handlers\base.py:142] Not Found: /media/img/activity/default_poster_pic
[15/Nov/2012 09:46:05] WARNING [django.request:e:\server-env\lib\site-packages\django\core\handlers\base.py:142] Not Found: /media/img/activity/default_poster_pic
[15/Nov/2012 09:46:05] WARNING [django.request:e:\server-env\lib\site-packages\django\core\handlers\base.py:142] Not Found: /media/img/activity/default_poster_pic
[15/Nov/2012 10:02:41] ERROR [django.request:e:\server-env\lib\site-packages\django\core\handlers\base.py:215] Internal Server Error: /activity/create/
Traceback (most recent call last):
  File "E:\server-env\lib\site-packages\django\core\handlers\base.py", line 111, in get_response
    response = callback(request, *callback_args, **callback_kwargs)
  File "E:\server-env\lib\site-packages\django\contrib\auth\decorators.py", line 20, in _wrapped_view
    return view_func(request, *args, **kwargs)
  File "E:\workspace\xz_server_from_GIT\xzserver\repo.server\xizhi-server\apps\activity\views.py", line 89, in createActivity
    return HttpResponseRedirect(reverse("activity_poster_form", args=[act.id]))  # redirct to activity detail page
  File "E:\server-env\lib\site-packages\django\core\urlresolvers.py", line 476, in reverse
    return iri_to_uri(resolver._reverse_with_prefix(view, prefix, *args, **kwargs))
  File "E:\server-env\lib\site-packages\django\core\urlresolvers.py", line 396, in _reverse_with_prefix
    "arguments '%s' not found." % (lookup_view_s, args, kwargs))
NoReverseMatch: Reverse for 'activity_poster_form' with arguments '(58L,)' and keyword arguments '{}' not found.
[15/Nov/2012 10:02:41] ERROR [django.request:e:\server-env\lib\site-packages\django\core\handlers\base.py:215] Internal Server Error: /activity/create/
Traceback (most recent call last):
  File "E:\server-env\lib\site-packages\django\core\handlers\base.py", line 111, in get_response
    response = callback(request, *callback_args, **callback_kwargs)
  File "E:\server-env\lib\site-packages\django\contrib\auth\decorators.py", line 20, in _wrapped_view
    return view_func(request, *args, **kwargs)
  File "E:\workspace\xz_server_from_GIT\xzserver\repo.server\xizhi-server\apps\activity\views.py", line 89, in createActivity
    return HttpResponseRedirect(reverse("activity_poster_form", args=[act.id]))  # redirct to activity detail page
  File "E:\server-env\lib\site-packages\django\core\urlresolvers.py", line 476, in reverse
    return iri_to_uri(resolver._reverse_with_prefix(view, prefix, *args, **kwargs))
  File "E:\server-env\lib\site-packages\django\core\urlresolvers.py", line 396, in _reverse_with_prefix
    "arguments '%s' not found." % (lookup_view_s, args, kwargs))
NoReverseMatch: Reverse for 'activity_poster_form' with arguments '(58L,)' and keyword arguments '{}' not found.
[15/Nov/2012 10:03:41] ERROR [django.request:e:\server-env\lib\site-packages\django\core\handlers\base.py:215] Internal Server Error: /activity/create/
Traceback (most recent call last):
  File "E:\server-env\lib\site-packages\django\core\handlers\base.py", line 111, in get_response
    response = callback(request, *callback_args, **callback_kwargs)
  File "E:\server-env\lib\site-packages\django\contrib\auth\decorators.py", line 20, in _wrapped_view
    return view_func(request, *args, **kwargs)
  File "E:\workspace\xz_server_from_GIT\xzserver\repo.server\xizhi-server\apps\activity\views.py", line 89, in createActivity
    return HttpResponseRedirect(reverse('activity_poster_form', args=[act.id]))  # redirct to activity detail page
  File "E:\server-env\lib\site-packages\django\core\urlresolvers.py", line 476, in reverse
    return iri_to_uri(resolver._reverse_with_prefix(view, prefix, *args, **kwargs))
  File "E:\server-env\lib\site-packages\django\core\urlresolvers.py", line 396, in _reverse_with_prefix
    "arguments '%s' not found." % (lookup_view_s, args, kwargs))
NoReverseMatch: Reverse for 'activity_poster_form' with arguments '(59L,)' and keyword arguments '{}' not found.
[15/Nov/2012 10:03:41] ERROR [django.request:e:\server-env\lib\site-packages\django\core\handlers\base.py:215] Internal Server Error: /activity/create/
Traceback (most recent call last):
  File "E:\server-env\lib\site-packages\django\core\handlers\base.py", line 111, in get_response
    response = callback(request, *callback_args, **callback_kwargs)
  File "E:\server-env\lib\site-packages\django\contrib\auth\decorators.py", line 20, in _wrapped_view
    return view_func(request, *args, **kwargs)
  File "E:\workspace\xz_server_from_GIT\xzserver\repo.server\xizhi-server\apps\activity\views.py", line 89, in createActivity
    return HttpResponseRedirect(reverse('activity_poster_form', args=[act.id]))  # redirct to activity detail page
  File "E:\server-env\lib\site-packages\django\core\urlresolvers.py", line 476, in reverse
    return iri_to_uri(resolver._reverse_with_prefix(view, prefix, *args, **kwargs))
  File "E:\server-env\lib\site-packages\django\core\urlresolvers.py", line 396, in _reverse_with_prefix
    "arguments '%s' not found." % (lookup_view_s, args, kwargs))
NoReverseMatch: Reverse for 'activity_poster_form' with arguments '(59L,)' and keyword arguments '{}' not found.
[15/Nov/2012 10:05:18] ERROR [django.request:e:\server-env\lib\site-packages\django\core\handlers\base.py:215] Internal Server Error: /activity/create/
Traceback (most recent call last):
  File "E:\server-env\lib\site-packages\django\core\handlers\base.py", line 111, in get_response
    response = callback(request, *callback_args, **callback_kwargs)
  File "E:\server-env\lib\site-packages\django\contrib\auth\decorators.py", line 20, in _wrapped_view
    return view_func(request, *args, **kwargs)
  File "E:\workspace\xz_server_from_GIT\xzserver\repo.server\xizhi-server\apps\activity\views.py", line 89, in createActivity
    return HttpResponseRedirect(reverse('activity_poster_form', args=80))  # redirct to activity detail page
  File "E:\server-env\lib\site-packages\django\core\urlresolvers.py", line 476, in reverse
    return iri_to_uri(resolver._reverse_with_prefix(view, prefix, *args, **kwargs))
TypeError: _reverse_with_prefix() argument after * must be a sequence, not int
[15/Nov/2012 10:05:18] ERROR [django.request:e:\server-env\lib\site-packages\django\core\handlers\base.py:215] Internal Server Error: /activity/create/
Traceback (most recent call last):
  File "E:\server-env\lib\site-packages\django\core\handlers\base.py", line 111, in get_response
    response = callback(request, *callback_args, **callback_kwargs)
  File "E:\server-env\lib\site-packages\django\contrib\auth\decorators.py", line 20, in _wrapped_view
    return view_func(request, *args, **kwargs)
  File "E:\workspace\xz_server_from_GIT\xzserver\repo.server\xizhi-server\apps\activity\views.py", line 89, in createActivity
    return HttpResponseRedirect(reverse('activity_poster_form', args=80))  # redirct to activity detail page
  File "E:\server-env\lib\site-packages\django\core\urlresolvers.py", line 476, in reverse
    return iri_to_uri(resolver._reverse_with_prefix(view, prefix, *args, **kwargs))
TypeError: _reverse_with_prefix() argument after * must be a sequence, not int
[15/Nov/2012 10:05:34] ERROR [django.request:e:\server-env\lib\site-packages\django\core\handlers\base.py:215] Internal Server Error: /activity/create/
Traceback (most recent call last):
  File "E:\server-env\lib\site-packages\django\core\handlers\base.py", line 111, in get_response
    response = callback(request, *callback_args, **callback_kwargs)
  File "E:\server-env\lib\site-packages\django\contrib\auth\decorators.py", line 20, in _wrapped_view
    return view_func(request, *args, **kwargs)
  File "E:\workspace\xz_server_from_GIT\xzserver\repo.server\xizhi-server\apps\activity\views.py", line 89, in createActivity
    return HttpResponseRedirect(reverse('activity_poster_form', args='80'))  # redirct to activity detail page
  File "E:\server-env\lib\site-packages\django\core\urlresolvers.py", line 476, in reverse
    return iri_to_uri(resolver._reverse_with_prefix(view, prefix, *args, **kwargs))
  File "E:\server-env\lib\site-packages\django\core\urlresolvers.py", line 396, in _reverse_with_prefix
    "arguments '%s' not found." % (lookup_view_s, args, kwargs))
NoReverseMatch: Reverse for 'activity_poster_form' with arguments '('8', '0')' and keyword arguments '{}' not found.
[15/Nov/2012 10:05:34] ERROR [django.request:e:\server-env\lib\site-packages\django\core\handlers\base.py:215] Internal Server Error: /activity/create/
Traceback (most recent call last):
  File "E:\server-env\lib\site-packages\django\core\handlers\base.py", line 111, in get_response
    response = callback(request, *callback_args, **callback_kwargs)
  File "E:\server-env\lib\site-packages\django\contrib\auth\decorators.py", line 20, in _wrapped_view
    return view_func(request, *args, **kwargs)
  File "E:\workspace\xz_server_from_GIT\xzserver\repo.server\xizhi-server\apps\activity\views.py", line 89, in createActivity
    return HttpResponseRedirect(reverse('activity_poster_form', args='80'))  # redirct to activity detail page
  File "E:\server-env\lib\site-packages\django\core\urlresolvers.py", line 476, in reverse
    return iri_to_uri(resolver._reverse_with_prefix(view, prefix, *args, **kwargs))
  File "E:\server-env\lib\site-packages\django\core\urlresolvers.py", line 396, in _reverse_with_prefix
    "arguments '%s' not found." % (lookup_view_s, args, kwargs))
NoReverseMatch: Reverse for 'activity_poster_form' with arguments '('8', '0')' and keyword arguments '{}' not found.
[15/Nov/2012 10:07:50] ERROR [django.request:e:\server-env\lib\site-packages\django\core\handlers\base.py:215] Internal Server Error: /activity/create/
Traceback (most recent call last):
  File "E:\server-env\lib\site-packages\django\core\handlers\base.py", line 111, in get_response
    response = callback(request, *callback_args, **callback_kwargs)
  File "E:\server-env\lib\site-packages\django\contrib\auth\decorators.py", line 20, in _wrapped_view
    return view_func(request, *args, **kwargs)
  File "E:\workspace\xz_server_from_GIT\xzserver\repo.server\xizhi-server\apps\activity\views.py", line 89, in createActivity
    return HttpResponseRedirect(reverse('activity_poster_form', args=[act.id]))  # redirct to activity detail page
  File "E:\server-env\lib\site-packages\django\core\urlresolvers.py", line 476, in reverse
    return iri_to_uri(resolver._reverse_with_prefix(view, prefix, *args, **kwargs))
  File "E:\server-env\lib\site-packages\django\core\urlresolvers.py", line 396, in _reverse_with_prefix
    "arguments '%s' not found." % (lookup_view_s, args, kwargs))
NoReverseMatch: Reverse for 'activity_poster_form' with arguments '(62L,)' and keyword arguments '{}' not found.
[15/Nov/2012 10:07:50] ERROR [django.request:e:\server-env\lib\site-packages\django\core\handlers\base.py:215] Internal Server Error: /activity/create/
Traceback (most recent call last):
  File "E:\server-env\lib\site-packages\django\core\handlers\base.py", line 111, in get_response
    response = callback(request, *callback_args, **callback_kwargs)
  File "E:\server-env\lib\site-packages\django\contrib\auth\decorators.py", line 20, in _wrapped_view
    return view_func(request, *args, **kwargs)
  File "E:\workspace\xz_server_from_GIT\xzserver\repo.server\xizhi-server\apps\activity\views.py", line 89, in createActivity
    return HttpResponseRedirect(reverse('activity_poster_form', args=[act.id]))  # redirct to activity detail page
  File "E:\server-env\lib\site-packages\django\core\urlresolvers.py", line 476, in reverse
    return iri_to_uri(resolver._reverse_with_prefix(view, prefix, *args, **kwargs))
  File "E:\server-env\lib\site-packages\django\core\urlresolvers.py", line 396, in _reverse_with_prefix
    "arguments '%s' not found." % (lookup_view_s, args, kwargs))
NoReverseMatch: Reverse for 'activity_poster_form' with arguments '(62L,)' and keyword arguments '{}' not found.
[15/Nov/2012 10:09:05] WARNING [django.request:e:\server-env\lib\site-packages\django\core\handlers\base.py:142] Not Found: /media/img/activity/
[15/Nov/2012 10:09:05] WARNING [django.request:e:\server-env\lib\site-packages\django\core\handlers\base.py:142] Not Found: /media/img/activity/
[15/Nov/2012 10:09:05] WARNING [django.request:e:\server-env\lib\site-packages\django\core\handlers\base.py:142] Not Found: /media/img/activity/
[15/Nov/2012 10:09:05] WARNING [django.request:e:\server-env\lib\site-packages\django\core\handlers\base.py:142] Not Found: /media/img/activity/
[15/Nov/2012 10:09:09] ERROR [django.request:e:\server-env\lib\site-packages\django\core\handlers\base.py:215] Internal Server Error: /activity/upload_post/
Traceback (most recent call last):
  File "E:\server-env\lib\site-packages\django\core\handlers\base.py", line 111, in get_response
    response = callback(request, *callback_args, **callback_kwargs)
  File "E:\server-env\lib\site-packages\django\contrib\auth\decorators.py", line 20, in _wrapped_view
    return view_func(request, *args, **kwargs)
  File "E:\workspace\xz_server_from_GIT\xzserver\repo.server\xizhi-server\apps\activity\views.py", line 100, in initPoster
    act = Activity.objects.get(id=actId)
  File "E:\server-env\lib\site-packages\django\db\models\manager.py", line 131, in get
    return self.get_query_set().get(*args, **kwargs)
  File "E:\server-env\lib\site-packages\django\db\models\query.py", line 358, in get
    clone = self.filter(*args, **kwargs)
  File "E:\server-env\lib\site-packages\django\db\models\query.py", line 624, in filter
    return self._filter_or_exclude(False, *args, **kwargs)
  File "E:\server-env\lib\site-packages\django\db\models\query.py", line 642, in _filter_or_exclude
    clone.query.add_q(Q(*args, **kwargs))
  File "E:\server-env\lib\site-packages\django\db\models\sql\query.py", line 1250, in add_q
    can_reuse=used_aliases, force_having=force_having)
  File "E:\server-env\lib\site-packages\django\db\models\sql\query.py", line 1185, in add_filter
    connector)
  File "E:\server-env\lib\site-packages\django\db\models\sql\where.py", line 69, in add
    value = obj.prepare(lookup_type, value)
  File "E:\server-env\lib\site-packages\django\db\models\sql\where.py", line 320, in prepare
    return self.field.get_prep_lookup(lookup_type, value)
  File "E:\server-env\lib\site-packages\django\db\models\fields\__init__.py", line 310, in get_prep_lookup
    return self.get_prep_value(value)
  File "E:\server-env\lib\site-packages\django\db\models\fields\__init__.py", line 537, in get_prep_value
    return int(value)
ValueError: invalid literal for int() with base 10: ''
[15/Nov/2012 10:09:09] ERROR [django.request:e:\server-env\lib\site-packages\django\core\handlers\base.py:215] Internal Server Error: /activity/upload_post/
Traceback (most recent call last):
  File "E:\server-env\lib\site-packages\django\core\handlers\base.py", line 111, in get_response
    response = callback(request, *callback_args, **callback_kwargs)
  File "E:\server-env\lib\site-packages\django\contrib\auth\decorators.py", line 20, in _wrapped_view
    return view_func(request, *args, **kwargs)
  File "E:\workspace\xz_server_from_GIT\xzserver\repo.server\xizhi-server\apps\activity\views.py", line 100, in initPoster
    act = Activity.objects.get(id=actId)
  File "E:\server-env\lib\site-packages\django\db\models\manager.py", line 131, in get
    return self.get_query_set().get(*args, **kwargs)
  File "E:\server-env\lib\site-packages\django\db\models\query.py", line 358, in get
    clone = self.filter(*args, **kwargs)
  File "E:\server-env\lib\site-packages\django\db\models\query.py", line 624, in filter
    return self._filter_or_exclude(False, *args, **kwargs)
  File "E:\server-env\lib\site-packages\django\db\models\query.py", line 642, in _filter_or_exclude
    clone.query.add_q(Q(*args, **kwargs))
  File "E:\server-env\lib\site-packages\django\db\models\sql\query.py", line 1250, in add_q
    can_reuse=used_aliases, force_having=force_having)
  File "E:\server-env\lib\site-packages\django\db\models\sql\query.py", line 1185, in add_filter
    connector)
  File "E:\server-env\lib\site-packages\django\db\models\sql\where.py", line 69, in add
    value = obj.prepare(lookup_type, value)
  File "E:\server-env\lib\site-packages\django\db\models\sql\where.py", line 320, in prepare
    return self.field.get_prep_lookup(lookup_type, value)
  File "E:\server-env\lib\site-packages\django\db\models\fields\__init__.py", line 310, in get_prep_lookup
    return self.get_prep_value(value)
  File "E:\server-env\lib\site-packages\django\db\models\fields\__init__.py", line 537, in get_prep_value
    return int(value)
ValueError: invalid literal for int() with base 10: ''
[15/Nov/2012 10:10:52] WARNING [django.request:e:\server-env\lib\site-packages\django\core\handlers\base.py:142] Not Found: /media/img/activity/
[15/Nov/2012 10:10:52] WARNING [django.request:e:\server-env\lib\site-packages\django\core\handlers\base.py:142] Not Found: /media/img/activity/
[15/Nov/2012 10:10:52] WARNING [django.request:e:\server-env\lib\site-packages\django\core\handlers\base.py:142] Not Found: /media/img/activity/
[15/Nov/2012 10:10:52] WARNING [django.request:e:\server-env\lib\site-packages\django\core\handlers\base.py:142] Not Found: /media/img/activity/
[15/Nov/2012 10:10:56] ERROR [django.request:e:\server-env\lib\site-packages\django\core\handlers\base.py:215] Internal Server Error: /activity/upload_post/
Traceback (most recent call last):
  File "E:\server-env\lib\site-packages\django\core\handlers\base.py", line 111, in get_response
    response = callback(request, *callback_args, **callback_kwargs)
  File "E:\server-env\lib\site-packages\django\contrib\auth\decorators.py", line 20, in _wrapped_view
    return view_func(request, *args, **kwargs)
  File "E:\workspace\xz_server_from_GIT\xzserver\repo.server\xizhi-server\apps\activity\views.py", line 100, in initPoster
    act = Activity.objects.get(id=int(actId))
ValueError: invalid literal for int() with base 10: ''
[15/Nov/2012 10:10:56] ERROR [django.request:e:\server-env\lib\site-packages\django\core\handlers\base.py:215] Internal Server Error: /activity/upload_post/
Traceback (most recent call last):
  File "E:\server-env\lib\site-packages\django\core\handlers\base.py", line 111, in get_response
    response = callback(request, *callback_args, **callback_kwargs)
  File "E:\server-env\lib\site-packages\django\contrib\auth\decorators.py", line 20, in _wrapped_view
    return view_func(request, *args, **kwargs)
  File "E:\workspace\xz_server_from_GIT\xzserver\repo.server\xizhi-server\apps\activity\views.py", line 100, in initPoster
    act = Activity.objects.get(id=int(actId))
ValueError: invalid literal for int() with base 10: ''
[15/Nov/2012 10:13:49] ERROR [django.request:e:\server-env\lib\site-packages\django\core\handlers\base.py:215] Internal Server Error: /activity/upload_post/
Traceback (most recent call last):
  File "E:\server-env\lib\site-packages\django\core\handlers\base.py", line 111, in get_response
    response = callback(request, *callback_args, **callback_kwargs)
  File "E:\server-env\lib\site-packages\django\contrib\auth\decorators.py", line 20, in _wrapped_view
    return view_func(request, *args, **kwargs)
  File "E:\workspace\xz_server_from_GIT\xzserver\repo.server\xizhi-server\apps\activity\views.py", line 100, in initPoster
    act = Activity.objects.get(id=int(actId))
ValueError: invalid literal for int() with base 10: ''
[15/Nov/2012 10:13:49] ERROR [django.request:e:\server-env\lib\site-packages\django\core\handlers\base.py:215] Internal Server Error: /activity/upload_post/
Traceback (most recent call last):
  File "E:\server-env\lib\site-packages\django\core\handlers\base.py", line 111, in get_response
    response = callback(request, *callback_args, **callback_kwargs)
  File "E:\server-env\lib\site-packages\django\contrib\auth\decorators.py", line 20, in _wrapped_view
    return view_func(request, *args, **kwargs)
  File "E:\workspace\xz_server_from_GIT\xzserver\repo.server\xizhi-server\apps\activity\views.py", line 100, in initPoster
    act = Activity.objects.get(id=int(actId))
ValueError: invalid literal for int() with base 10: ''
[15/Nov/2012 10:14:39] ERROR [django.request:e:\server-env\lib\site-packages\django\core\handlers\base.py:215] Internal Server Error: /activity/upload_post/
Traceback (most recent call last):
  File "E:\server-env\lib\site-packages\django\core\handlers\base.py", line 111, in get_response
    response = callback(request, *callback_args, **callback_kwargs)
  File "E:\server-env\lib\site-packages\django\contrib\auth\decorators.py", line 20, in _wrapped_view
    return view_func(request, *args, **kwargs)
  File "E:\workspace\xz_server_from_GIT\xzserver\repo.server\xizhi-server\apps\activity\views.py", line 107, in initPoster
    tmpname = img_utils.upload(posterPic, settings.POSTER_WHAT, settings.POSTER_SIZE_BIG,
  File "E:\server-env\lib\site-packages\django\utils\functional.py", line 185, in inner
    return func(self._wrapped, *args)
AttributeError: 'Settings' object has no attribute 'POSTER_WHAT'
[15/Nov/2012 10:14:39] ERROR [django.request:e:\server-env\lib\site-packages\django\core\handlers\base.py:215] Internal Server Error: /activity/upload_post/
Traceback (most recent call last):
  File "E:\server-env\lib\site-packages\django\core\handlers\base.py", line 111, in get_response
    response = callback(request, *callback_args, **callback_kwargs)
  File "E:\server-env\lib\site-packages\django\contrib\auth\decorators.py", line 20, in _wrapped_view
    return view_func(request, *args, **kwargs)
  File "E:\workspace\xz_server_from_GIT\xzserver\repo.server\xizhi-server\apps\activity\views.py", line 107, in initPoster
    tmpname = img_utils.upload(posterPic, settings.POSTER_WHAT, settings.POSTER_SIZE_BIG,
  File "E:\server-env\lib\site-packages\django\utils\functional.py", line 185, in inner
    return func(self._wrapped, *args)
AttributeError: 'Settings' object has no attribute 'POSTER_WHAT'
[15/Nov/2012 10:16:04] ERROR [mysite:e:\workspace\xz_server_from_git\xzserver\repo.server\xizhi-server\apps\common\img_utils.py:73] None
[15/Nov/2012 10:16:05] WARNING [django.request:e:\server-env\lib\site-packages\django\core\handlers\base.py:142] Not Found: /media/img/activity/None
[15/Nov/2012 10:16:05] WARNING [django.request:e:\server-env\lib\site-packages\django\core\handlers\base.py:142] Not Found: /media/img/activity/None
[15/Nov/2012 10:16:05] WARNING [django.request:e:\server-env\lib\site-packages\django\core\handlers\base.py:142] Not Found: /media/img/activity/None
[15/Nov/2012 10:16:05] WARNING [django.request:e:\server-env\lib\site-packages\django\core\handlers\base.py:142] Not Found: /media/img/activity/None
[15/Nov/2012 10:21:29] WARNING [django.request:e:\server-env\lib\site-packages\django\core\handlers\base.py:142] Not Found: /media/img/
[15/Nov/2012 10:21:29] WARNING [django.request:e:\server-env\lib\site-packages\django\core\handlers\base.py:142] Not Found: /media/img/
[15/Nov/2012 10:23:41] WARNING [django.request:e:\server-env\lib\site-packages\django\core\handlers\base.py:142] Not Found: /account/login/
[15/Nov/2012 10:23:41] WARNING [django.request:e:\server-env\lib\site-packages\django\core\handlers\base.py:142] Not Found: /account/login/
[15/Nov/2012 14:12:14] WARNING [django.request:e:\server-env\lib\site-packages\django\core\handlers\base.py:142] Not Found: /favicon.ico
[15/Nov/2012 14:12:14] WARNING [django.request:e:\server-env\lib\site-packages\django\core\handlers\base.py:142] Not Found: /favicon.ico
[15/Nov/2012 14:12:15] DEBUG [mysite:e:\workspace\xz_server_from_git\xzserver\repo.server\xizhi-server\apps\account\views.py:160] login_count: 44 of profile: 2
[15/Nov/2012 14:12:18] WARNING [django.request:e:\server-env\lib\site-packages\django\core\handlers\base.py:142] Not Found: /favicon.ico
[15/Nov/2012 14:12:18] WARNING [django.request:e:\server-env\lib\site-packages\django\core\handlers\base.py:142] Not Found: /favicon.ico
[15/Nov/2012 14:12:22] WARNING [django.request:e:\server-env\lib\site-packages\django\core\handlers\base.py:142] Not Found: /favicon.ico
[15/Nov/2012 14:12:22] WARNING [django.request:e:\server-env\lib\site-packages\django\core\handlers\base.py:142] Not Found: /favicon.ico
[15/Nov/2012 14:12:26] WARNING [django.request:e:\server-env\lib\site-packages\django\core\handlers\base.py:142] Not Found: /favicon.ico
[15/Nov/2012 14:12:26] WARNING [django.request:e:\server-env\lib\site-packages\django\core\handlers\base.py:142] Not Found: /favicon.ico
[15/Nov/2012 14:12:29] WARNING [django.request:e:\server-env\lib\site-packages\django\core\handlers\base.py:142] Not Found: /favicon.ico
[15/Nov/2012 14:12:29] WARNING [django.request:e:\server-env\lib\site-packages\django\core\handlers\base.py:142] Not Found: /favicon.ico
[15/Nov/2012 14:12:31] WARNING [django.request:e:\server-env\lib\site-packages\django\core\handlers\base.py:142] Not Found: /favicon.ico
[15/Nov/2012 14:12:31] WARNING [django.request:e:\server-env\lib\site-packages\django\core\handlers\base.py:142] Not Found: /favicon.ico
[15/Nov/2012 14:12:32] WARNING [django.request:e:\server-env\lib\site-packages\django\core\handlers\base.py:142] Not Found: /favicon.ico
[15/Nov/2012 14:12:32] WARNING [django.request:e:\server-env\lib\site-packages\django\core\handlers\base.py:142] Not Found: /favicon.ico
[15/Nov/2012 14:13:55] WARNING [django.request:e:\server-env\lib\site-packages\django\core\handlers\base.py:142] Not Found: /favicon.ico
[15/Nov/2012 14:13:55] WARNING [django.request:e:\server-env\lib\site-packages\django\core\handlers\base.py:142] Not Found: /favicon.ico
[15/Nov/2012 14:13:57] WARNING [django.request:e:\server-env\lib\site-packages\django\core\handlers\base.py:142] Not Found: /favicon.ico
[15/Nov/2012 14:13:57] WARNING [django.request:e:\server-env\lib\site-packages\django\core\handlers\base.py:142] Not Found: /favicon.ico
[15/Nov/2012 14:13:59] WARNING [django.request:e:\server-env\lib\site-packages\django\core\handlers\base.py:142] Not Found: /favicon.ico
[15/Nov/2012 14:13:59] WARNING [django.request:e:\server-env\lib\site-packages\django\core\handlers\base.py:142] Not Found: /favicon.ico
[15/Nov/2012 14:14:02] WARNING [django.request:e:\server-env\lib\site-packages\django\core\handlers\base.py:142] Not Found: /favicon.ico
[15/Nov/2012 14:14:02] WARNING [django.request:e:\server-env\lib\site-packages\django\core\handlers\base.py:142] Not Found: /favicon.ico
[15/Nov/2012 14:14:33] WARNING [django.request:e:\server-env\lib\site-packages\django\core\handlers\base.py:142] Not Found: /favicon.ico
[15/Nov/2012 14:14:33] WARNING [django.request:e:\server-env\lib\site-packages\django\core\handlers\base.py:142] Not Found: /favicon.ico
[15/Nov/2012 14:14:36] WARNING [django.request:e:\server-env\lib\site-packages\django\core\handlers\base.py:142] Not Found: /favicon.ico
[15/Nov/2012 14:14:36] WARNING [django.request:e:\server-env\lib\site-packages\django\core\handlers\base.py:142] Not Found: /favicon.ico
[15/Nov/2012 14:14:37] WARNING [django.request:e:\server-env\lib\site-packages\django\core\handlers\base.py:142] Not Found: /favicon.ico
[15/Nov/2012 14:14:37] WARNING [django.request:e:\server-env\lib\site-packages\django\core\handlers\base.py:142] Not Found: /favicon.ico
[15/Nov/2012 14:14:51] WARNING [django.request:e:\server-env\lib\site-packages\django\core\handlers\base.py:142] Not Found: /favicon.ico
[15/Nov/2012 14:14:51] WARNING [django.request:e:\server-env\lib\site-packages\django\core\handlers\base.py:142] Not Found: /favicon.ico
[15/Nov/2012 14:14:52] WARNING [django.request:e:\server-env\lib\site-packages\django\core\handlers\base.py:142] Not Found: /favicon.ico
[15/Nov/2012 14:14:52] WARNING [django.request:e:\server-env\lib\site-packages\django\core\handlers\base.py:142] Not Found: /favicon.ico
[15/Nov/2012 14:14:54] WARNING [django.request:e:\server-env\lib\site-packages\django\core\handlers\base.py:142] Not Found: /favicon.ico
[15/Nov/2012 14:14:54] WARNING [django.request:e:\server-env\lib\site-packages\django\core\handlers\base.py:142] Not Found: /favicon.ico
[15/Nov/2012 14:14:55] WARNING [django.request:e:\server-env\lib\site-packages\django\core\handlers\base.py:142] Not Found: /favicon.ico
[15/Nov/2012 14:14:55] WARNING [django.request:e:\server-env\lib\site-packages\django\core\handlers\base.py:142] Not Found: /favicon.ico
[15/Nov/2012 14:15:25] WARNING [django.request:e:\server-env\lib\site-packages\django\core\handlers\base.py:142] Not Found: /favicon.ico
[15/Nov/2012 14:15:25] WARNING [django.request:e:\server-env\lib\site-packages\django\core\handlers\base.py:142] Not Found: /favicon.ico
[15/Nov/2012 14:15:27] WARNING [django.request:e:\server-env\lib\site-packages\django\core\handlers\base.py:142] Not Found: /favicon.ico
[15/Nov/2012 14:15:27] WARNING [django.request:e:\server-env\lib\site-packages\django\core\handlers\base.py:142] Not Found: /favicon.ico
[15/Nov/2012 14:19:13] ERROR [django.request:e:\server-env\lib\site-packages\django\core\handlers\base.py:215] Internal Server Error: /profiles/save_profile/
Traceback (most recent call last):
  File "E:\server-env\lib\site-packages\django\core\handlers\base.py", line 129, in get_response
    raise ValueError("The view %s.%s didn't return an HttpResponse object." % (callback.__module__, view_name))
ValueError: The view profiles.views.save_profile didn't return an HttpResponse object.
[15/Nov/2012 14:19:13] ERROR [django.request:e:\server-env\lib\site-packages\django\core\handlers\base.py:215] Internal Server Error: /profiles/save_profile/
Traceback (most recent call last):
  File "E:\server-env\lib\site-packages\django\core\handlers\base.py", line 129, in get_response
    raise ValueError("The view %s.%s didn't return an HttpResponse object." % (callback.__module__, view_name))
ValueError: The view profiles.views.save_profile didn't return an HttpResponse object.
[15/Nov/2012 14:21:09] DEBUG [mysite:e:\workspace\xz_server_from_git\xzserver\repo.server\xizhi-server\apps\common\img_utils.py:54] File with name a51e4480-2eec-11e2-a8c8-00e06650caff saved
[15/Nov/2012 14:21:15] DEBUG [mysite:e:\workspace\xz_server_from_git\xzserver\repo.server\xizhi-server\apps\profiles\views.py:241] (31, 18, 84, 71)
[15/Nov/2012 14:21:15] DEBUG [mysite:e:\workspace\xz_server_from_git\xzserver\repo.server\xizhi-server\apps\common\img_utils.py:54] File with name a8f5160f-2eec-11e2-8866-00e06650caff_b saved
[15/Nov/2012 14:21:15] DEBUG [mysite:e:\workspace\xz_server_from_git\xzserver\repo.server\xizhi-server\apps\common\img_utils.py:54] File with name a8f56430-2eec-11e2-a4aa-00e06650caff_n saved
[15/Nov/2012 14:21:15] DEBUG [mysite:e:\workspace\xz_server_from_git\xzserver\repo.server\xizhi-server\apps\common\img_utils.py:54] File with name a8f5b251-2eec-11e2-bad3-00e06650caff_s saved
[15/Nov/2012 14:25:39] WARNING [django.request:e:\server-env\lib\site-packages\django\core\handlers\base.py:142] Not Found: /profiles/save_profile/
[15/Nov/2012 14:25:39] WARNING [django.request:e:\server-env\lib\site-packages\django\core\handlers\base.py:142] Not Found: /profiles/save_profile/
[15/Nov/2012 15:21:22] ERROR [mysite:e:\workspace\xz_server_from_git\xzserver\repo.server\xizhi-server\apps\common\img_utils.py:73] None
[15/Nov/2012 15:21:22] WARNING [django.request:e:\server-env\lib\site-packages\django\core\handlers\base.py:142] Not Found: /media/img/activity/None
[15/Nov/2012 15:21:22] WARNING [django.request:e:\server-env\lib\site-packages\django\core\handlers\base.py:142] Not Found: /media/img/activity/None
[15/Nov/2012 15:21:23] WARNING [django.request:e:\server-env\lib\site-packages\django\core\handlers\base.py:142] Not Found: /media/img/activity/None
[15/Nov/2012 15:21:23] WARNING [django.request:e:\server-env\lib\site-packages\django\core\handlers\base.py:142] Not Found: /media/img/activity/None
